Removing miniconda version 22.11.1-1
Loading miniconda version 22.11.1-1
loading libiconv version 1.16
loading xz version 5.2.5
loading zlib version 1.2.11
loading libxml2 version 2.9.12
loading cuda version 11.8.0
[2024-09-22 20:40:22,111] [INFO] [real_accelerator.py:203:get_accelerator] Setting ds_accelerator to cuda (auto detect)
INFO:root:Using nproc_per_node=4.
W0922 20:40:30.961000 140522397386560 torch/distributed/run.py:779] 
W0922 20:40:30.961000 140522397386560 torch/distributed/run.py:779] *****************************************
W0922 20:40:30.961000 140522397386560 torch/distributed/run.py:779] Setting OMP_NUM_THREADS environment variable for each process to be 1 in default, to avoid your system being overloaded, please further tune the variable for optimal performance in your application as needed. 
W0922 20:40:30.961000 140522397386560 torch/distributed/run.py:779] *****************************************
  File "/work/pi_miyyer_umass_edu/ctpham/alignment-handbook/scripts/run_sft.py", line 16
    """
IndentationError: unexpected indent
  File "/work/pi_miyyer_umass_edu/ctpham/alignment-handbook/scripts/run_sft.py", line 16
    """
IndentationError: unexpected indent
  File "/work/pi_miyyer_umass_edu/ctpham/alignment-handbook/scripts/run_sft.py", line 16
    """
IndentationError: unexpected indent
  File "/work/pi_miyyer_umass_edu/ctpham/alignment-handbook/scripts/run_sft.py", line 16
    """
IndentationError: unexpected indent
E0922 20:40:31.096000 140522397386560 torch/distributed/elastic/multiprocessing/api.py:833] failed (exitcode: 1) local_rank: 0 (pid: 3295316) of binary: /home/ctpham_umass_edu/.conda/envs/handbook/bin/python3
Warning: The cache directory for DeepSpeed Triton autotune, /project/pi_miyyer_umass_edu/ctpham/.cache, appears to be on an NFS system. While this is generally acceptable, if you experience slowdowns or hanging when DeepSpeed exits, it is recommended to set the TRITON_CACHE_DIR environment variable to a non-NFS path.
Traceback (most recent call last):
  File "/home/ctpham_umass_edu/.conda/envs/handbook/bin/accelerate", line 8, in <module>
    sys.exit(main())
  File "/home/ctpham_umass_edu/.conda/envs/handbook/lib/python3.10/site-packages/accelerate/commands/accelerate_cli.py", line 48, in main
    args.func(args)
  File "/home/ctpham_umass_edu/.conda/envs/handbook/lib/python3.10/site-packages/accelerate/commands/launch.py", line 1159, in launch_command
    deepspeed_launcher(args)
  File "/home/ctpham_umass_edu/.conda/envs/handbook/lib/python3.10/site-packages/accelerate/commands/launch.py", line 852, in deepspeed_launcher
    distrib_run.run(args)
  File "/home/ctpham_umass_edu/.conda/envs/handbook/lib/python3.10/site-packages/torch/distributed/run.py", line 892, in run
    elastic_launch(
  File "/home/ctpham_umass_edu/.conda/envs/handbook/lib/python3.10/site-packages/torch/distributed/launcher/api.py", line 133, in __call__
    return launch_agent(self._config, self._entrypoint, list(args))
  File "/home/ctpham_umass_edu/.conda/envs/handbook/lib/python3.10/site-packages/torch/distributed/launcher/api.py", line 264, in launch_agent
    raise ChildFailedError(
torch.distributed.elastic.multiprocessing.errors.ChildFailedError: 
============================================================
scripts/run_sft.py FAILED
------------------------------------------------------------
Failures:
[1]:
  time      : 2024-09-22_20:40:31
  host      : gpu013.unity.rc.umass.edu
  rank      : 1 (local_rank: 1)
  exitcode  : 1 (pid: 3295317)
  error_file: <N/A>
  traceback : To enable traceback see: https://pytorch.org/docs/stable/elastic/errors.html
[2]:
  time      : 2024-09-22_20:40:31
  host      : gpu013.unity.rc.umass.edu
  rank      : 2 (local_rank: 2)
  exitcode  : 1 (pid: 3295318)
  error_file: <N/A>
  traceback : To enable traceback see: https://pytorch.org/docs/stable/elastic/errors.html
[3]:
  time      : 2024-09-22_20:40:31
  host      : gpu013.unity.rc.umass.edu
  rank      : 3 (local_rank: 3)
  exitcode  : 1 (pid: 3295319)
  error_file: <N/A>
  traceback : To enable traceback see: https://pytorch.org/docs/stable/elastic/errors.html
------------------------------------------------------------
Root Cause (first observed failure):
[0]:
  time      : 2024-09-22_20:40:31
  host      : gpu013.unity.rc.umass.edu
  rank      : 0 (local_rank: 0)
  exitcode  : 1 (pid: 3295316)
  error_file: <N/A>
  traceback : To enable traceback see: https://pytorch.org/docs/stable/elastic/errors.html
============================================================
